[2025-10-17T09:03:41.656+0000] {local_task_job_runner.py:120} INFO - ::group::Pre task execution logs
[2025-10-17T09:03:41.671+0000] {taskinstance.py:2076} INFO - Dependencies all met for dep_context=non-requeueable deps ti=<TaskInstance: dag3.task_randomNum manual__2025-10-17T09:03:35.093542+00:00 [queued]>
[2025-10-17T09:03:41.677+0000] {taskinstance.py:2076} INFO - Dependencies all met for dep_context=requeueable deps ti=<TaskInstance: dag3.task_randomNum manual__2025-10-17T09:03:35.093542+00:00 [queued]>
[2025-10-17T09:03:41.678+0000] {taskinstance.py:2306} INFO - Starting attempt 1 of 1
[2025-10-17T09:03:41.690+0000] {taskinstance.py:2330} INFO - Executing <Task(PythonOperator): task_randomNum> on 2025-10-17 09:03:35.093542+00:00
[2025-10-17T09:03:41.698+0000] {warnings.py:112} WARNING - /home/***/.local/lib/python3.12/site-packages/***/task/task_runner/standard_task_runner.py:61: DeprecationWarning: This process (pid=301) is multi-threaded, use of fork() may lead to deadlocks in the child.
  pid = os.fork()

[2025-10-17T09:03:41.700+0000] {standard_task_runner.py:63} INFO - Started process 303 to run task
[2025-10-17T09:03:41.700+0000] {standard_task_runner.py:90} INFO - Running: ['***', 'tasks', 'run', 'dag3', 'task_randomNum', 'manual__2025-10-17T09:03:35.093542+00:00', '--job-id', '263', '--raw', '--subdir', 'DAGS_FOLDER/dag3.py', '--cfg-path', '/tmp/tmptrholgbx']
[2025-10-17T09:03:41.702+0000] {standard_task_runner.py:91} INFO - Job 263: Subtask task_randomNum
[2025-10-17T09:03:41.717+0000] {warnings.py:112} WARNING - /home/***/.local/lib/python3.12/site-packages/***/settings.py:195: DeprecationWarning: The sql_alchemy_conn option in [core] has been moved to the sql_alchemy_conn option in [database] - the old setting has been used, but please update your config.
  SQL_ALCHEMY_CONN = conf.get("database", "SQL_ALCHEMY_CONN")

[2025-10-17T09:03:41.759+0000] {task_command.py:426} INFO - Running <TaskInstance: dag3.task_randomNum manual__2025-10-17T09:03:35.093542+00:00 [running]> on host 5b9dfa83b040
[2025-10-17T09:03:41.831+0000] {taskinstance.py:2648} INFO - Exporting env vars: AIRFLOW_CTX_DAG_OWNER='***' AIRFLOW_CTX_DAG_ID='dag3' AIRFLOW_CTX_TASK_ID='task_randomNum' AIRFLOW_CTX_EXECUTION_DATE='2025-10-17T09:03:35.093542+00:00' AIRFLOW_CTX_TRY_NUMBER='1' AIRFLOW_CTX_DAG_RUN_ID='manual__2025-10-17T09:03:35.093542+00:00'
[2025-10-17T09:03:41.833+0000] {taskinstance.py:430} INFO - ::endgroup::
[2025-10-17T09:03:41.834+0000] {taskinstance.py:441} INFO - ::group::Post task execution logs
[2025-10-17T09:03:41.835+0000] {taskinstance.py:2905} ERROR - Task failed with exception
Traceback (most recent call last):
  File "/home/airflow/.local/lib/python3.12/site-packages/airflow/models/taskinstance.py", line 465, in _execute_task
    result = _execute_callable(context=context, **execute_callable_kwargs)
             ^^^^^^^^^^^^^^^^^^^^^^^^^^^^^^^^^^^^^^^^^^^^^^^^^^^^^^^^^^^^^
  File "/home/airflow/.local/lib/python3.12/site-packages/airflow/models/taskinstance.py", line 432, in _execute_callable
    return execute_callable(context=context, **execute_callable_kwargs)
           ^^^^^^^^^^^^^^^^^^^^^^^^^^^^^^^^^^^^^^^^^^^^^^^^^^^^^^^^^^^^
  File "/home/airflow/.local/lib/python3.12/site-packages/airflow/models/baseoperator.py", line 401, in wrapper
    return func(self, *args, **kwargs)
           ^^^^^^^^^^^^^^^^^^^^^^^^^^^
  File "/home/airflow/.local/lib/python3.12/site-packages/airflow/operators/python.py", line 235, in execute
    return_value = self.execute_callable()
                   ^^^^^^^^^^^^^^^^^^^^^^^
  File "/home/airflow/.local/lib/python3.12/site-packages/airflow/operators/python.py", line 252, in execute_callable
    return self.python_callable(*self.op_args, **self.op_kwargs)
           ^^^^^^^^^^^^^^^^^^^^^^^^^^^^^^^^^^^^^^^^^^^^^^^^^^^^^
  File "/opt/airflow/dags/dag3.py", line 11, in save_nums
    with open(output_file, 'w') as f:
         ^^^^^^^^^^^^^^^^^^^^^^
FileNotFoundError: [Errno 2] No such file or directory: '/opt/airflow/shared/tmp/random.txt'
[2025-10-17T09:03:41.844+0000] {taskinstance.py:1206} INFO - Marking task as FAILED. dag_id=dag3, task_id=task_randomNum, run_id=manual__2025-10-17T09:03:35.093542+00:00, execution_date=20251017T090335, start_date=20251017T090341, end_date=20251017T090341
[2025-10-17T09:03:41.855+0000] {standard_task_runner.py:110} ERROR - Failed to execute job 263 for task task_randomNum ([Errno 2] No such file or directory: '/opt/airflow/shared/tmp/random.txt'; 303)
[2025-10-17T09:03:41.874+0000] {local_task_job_runner.py:240} INFO - Task exited with return code 1
[2025-10-17T09:03:41.889+0000] {taskinstance.py:3503} INFO - 0 downstream tasks scheduled from follow-on schedule check
[2025-10-17T09:03:41.891+0000] {local_task_job_runner.py:222} INFO - ::endgroup::
