[2025-10-17T09:04:15.632+0000] {local_task_job_runner.py:120} INFO - ::group::Pre task execution logs
[2025-10-17T09:04:15.649+0000] {taskinstance.py:2076} INFO - Dependencies all met for dep_context=non-requeueable deps ti=<TaskInstance: dag3.task_randomNum manual__2025-10-17T09:03:35.093542+00:00 [queued]>
[2025-10-17T09:04:15.656+0000] {taskinstance.py:2076} INFO - Dependencies all met for dep_context=requeueable deps ti=<TaskInstance: dag3.task_randomNum manual__2025-10-17T09:03:35.093542+00:00 [queued]>
[2025-10-17T09:04:15.657+0000] {taskinstance.py:2306} INFO - Starting attempt 2 of 2
[2025-10-17T09:04:15.668+0000] {taskinstance.py:2330} INFO - Executing <Task(PythonOperator): task_randomNum> on 2025-10-17 09:03:35.093542+00:00
[2025-10-17T09:04:15.675+0000] {warnings.py:112} WARNING - /home/***/.local/lib/python3.12/site-packages/***/task/task_runner/standard_task_runner.py:61: DeprecationWarning: This process (pid=323) is multi-threaded, use of fork() may lead to deadlocks in the child.
  pid = os.fork()

[2025-10-17T09:04:15.677+0000] {standard_task_runner.py:63} INFO - Started process 325 to run task
[2025-10-17T09:04:15.677+0000] {standard_task_runner.py:90} INFO - Running: ['***', 'tasks', 'run', 'dag3', 'task_randomNum', 'manual__2025-10-17T09:03:35.093542+00:00', '--job-id', '269', '--raw', '--subdir', 'DAGS_FOLDER/dag3.py', '--cfg-path', '/tmp/tmpd98_mas1']
[2025-10-17T09:04:15.679+0000] {standard_task_runner.py:91} INFO - Job 269: Subtask task_randomNum
[2025-10-17T09:04:15.691+0000] {warnings.py:112} WARNING - /home/***/.local/lib/python3.12/site-packages/***/settings.py:195: DeprecationWarning: The sql_alchemy_conn option in [core] has been moved to the sql_alchemy_conn option in [database] - the old setting has been used, but please update your config.
  SQL_ALCHEMY_CONN = conf.get("database", "SQL_ALCHEMY_CONN")

[2025-10-17T09:04:15.730+0000] {task_command.py:426} INFO - Running <TaskInstance: dag3.task_randomNum manual__2025-10-17T09:03:35.093542+00:00 [running]> on host 5b9dfa83b040
[2025-10-17T09:04:15.803+0000] {taskinstance.py:2648} INFO - Exporting env vars: AIRFLOW_CTX_DAG_OWNER='***' AIRFLOW_CTX_DAG_ID='dag3' AIRFLOW_CTX_TASK_ID='task_randomNum' AIRFLOW_CTX_EXECUTION_DATE='2025-10-17T09:03:35.093542+00:00' AIRFLOW_CTX_TRY_NUMBER='2' AIRFLOW_CTX_DAG_RUN_ID='manual__2025-10-17T09:03:35.093542+00:00'
[2025-10-17T09:04:15.805+0000] {taskinstance.py:430} INFO - ::endgroup::
[2025-10-17T09:04:15.810+0000] {taskinstance.py:441} INFO - ::group::Post task execution logs
[2025-10-17T09:04:15.810+0000] {taskinstance.py:2905} ERROR - Task failed with exception
Traceback (most recent call last):
  File "/home/airflow/.local/lib/python3.12/site-packages/airflow/models/taskinstance.py", line 465, in _execute_task
    result = _execute_callable(context=context, **execute_callable_kwargs)
             ^^^^^^^^^^^^^^^^^^^^^^^^^^^^^^^^^^^^^^^^^^^^^^^^^^^^^^^^^^^^^
  File "/home/airflow/.local/lib/python3.12/site-packages/airflow/models/taskinstance.py", line 432, in _execute_callable
    return execute_callable(context=context, **execute_callable_kwargs)
           ^^^^^^^^^^^^^^^^^^^^^^^^^^^^^^^^^^^^^^^^^^^^^^^^^^^^^^^^^^^^
  File "/home/airflow/.local/lib/python3.12/site-packages/airflow/models/baseoperator.py", line 401, in wrapper
    return func(self, *args, **kwargs)
           ^^^^^^^^^^^^^^^^^^^^^^^^^^^
  File "/home/airflow/.local/lib/python3.12/site-packages/airflow/operators/python.py", line 235, in execute
    return_value = self.execute_callable()
                   ^^^^^^^^^^^^^^^^^^^^^^^
  File "/home/airflow/.local/lib/python3.12/site-packages/airflow/operators/python.py", line 252, in execute_callable
    return self.python_callable(*self.op_args, **self.op_kwargs)
           ^^^^^^^^^^^^^^^^^^^^^^^^^^^^^^^^^^^^^^^^^^^^^^^^^^^^^
  File "/opt/airflow/dags/dag3.py", line 12, in save_nums
    for num in random_num:
TypeError: 'int' object is not iterable
[2025-10-17T09:04:15.820+0000] {taskinstance.py:1206} INFO - Marking task as FAILED. dag_id=dag3, task_id=task_randomNum, run_id=manual__2025-10-17T09:03:35.093542+00:00, execution_date=20251017T090335, start_date=20251017T090415, end_date=20251017T090415
[2025-10-17T09:04:15.830+0000] {standard_task_runner.py:110} ERROR - Failed to execute job 269 for task task_randomNum ('int' object is not iterable; 325)
[2025-10-17T09:04:15.851+0000] {local_task_job_runner.py:240} INFO - Task exited with return code 1
[2025-10-17T09:04:15.864+0000] {taskinstance.py:3503} INFO - 0 downstream tasks scheduled from follow-on schedule check
[2025-10-17T09:04:15.867+0000] {local_task_job_runner.py:222} INFO - ::endgroup::
